Workbook
Name Slicer_Channel: #N/A
Name Slicer_Country: #N/A
Name Slicer_Order_Month: #N/A
Name Slicer_Order_Month1: #N/A
Name Slicer_Product_Category: #N/A
Name Slicer_Region: #N/A
Name Slicer_Salesperson: #N/A
Name Slicer_Year_order_was_placed: #N/A
Name Slicer_Year_order_was_placed1: #N/A

Sheet Dashboard Visualization
F1: =IF(AND(ISBLANK($U$1),ISBLANK($U$2),ISBLANK($U$3)),"Sales Revenue & KPI Overview",IF(AND(NOT(ISBLANK($U$1)),NOT(ISBLANK($U$2)),NOT(ISBLANK($U$3))),"Full Impact Forecast",IF(AND(NOT(ISBLANK($U$1)),NOT(ISBLANK($U$2))),"Projected Revenue with Discount Cap & Cost Inflation",IF(AND(NOT(ISBLANK($U$2)),NOT(ISBLANK($U$3))),"Revenue with Volume Growth & Cost Inflation",IF(AND(NOT(ISBLANK($U$1)),NOT(ISBLANK($U$3))),"Revenue with Discount Cap & Volume Growth",IF(AND(ISBLANK($U$2),ISBLANK($U$3)),"Global Discount Forecast",IF(AND(ISBLANK($U$1),ISBLANK($U$3)),"Cost Inflation Forecast","Target Volume Forecast"))))))) -> Sales Revenue & KPI Overview | T1: Global Discount Cap
T2: Unit Cost Inflation
F3: Total gross revenue | H3: Gross profit | J3: % profit margin | M3: Average order value | P3: Leadtime <=7 | T3: Increased quantities
F4: =SUM('Working Data'!$U:$U) -> 9639609.1 | H4: =SUM('Working Data'!$V:$V) -> 2111861.4 | J4: =AVERAGE('Working Data'!$W:$W) -> 0.22130624 | M4: =AVERAGE('Working Data'!$U:$U) -> 15252.546 | P4: =COUNTIF('Working Data'!$D:$D,"<=7")/COUNT('Working Data'!$D:$D) -> 0.23076923

Sheet Dashboard Pivots
A3: Row Labels | B3: Sum of Gross Revenue | H3: Sum of Gross Profit | I3: Column Labels | R3: Row Labels | S3: Sum of Gross Profit | T3: Average of Profit Margin % | X3: Order ID | Y3: Region | Z3: Quarter2 | AA3: Unit Cost | AB3: Discount % limits | AE3: Order ID | AF3: Region | AG3: Quarter2 | AH3: Unit Cost | AI3: Discount % limits
A4: Jan | B4: 625592.71 | H4: Row Labels | I4: Direct | J4: Distributor | K4: Marketplace | L4: Online | M4: Retail | N4: Unattributed | O4: Grand Total | R4: NET-2365 | S4: 65188.66 | T4: 0.59672531 | X4: ORD-2023-107265 | Y4: Asia | Z4: Q2 | AA4: 1209.22 | AB4: 0.1-0.2 | AE4: =X4 -> ORD-2023-107265 | AF4: =Y4 -> Asia | AG4: =Z4 -> Q2 | AH4: =AA4 -> 1209.22 | AI4: =AB4 -> 0.1-0.2
A5: Feb | B5: 849078.84 | H5: Africa | I5: 127780.36 | J5: 115663.95 | K5: 96681.534 | L5: 93027.888 | M5: 87748.836 | N5: 12862.258 | O5: 533764.83 | R5: NET-5987 | S5: 45921.93 | T5: 0.5716359 | X5: ORD-2023-109927 | Y5: Asia | Z5: Q3 | AA5: 946.99 | AB5: 0.1-0.2 | AE5: =X5 -> ORD-2023-109927 | AF5: =Y5 -> Asia | AG5: =Z5 -> Q3 | AH5: =AA5 -> 946.99 | AI5: =AB5 -> 0.1-0.2
A6: Mar | B6: 699940.28 | H6: Americas | I6: 175514.37 | J6: 104438.95 | K6: 53060.275 | L6: 181844.58 | M6: 27320.006 | N6: 777.96 | O6: 542956.14 | R6: LAP-3904 | S6: 42149.286 | T6: 0.51806221 | X6: ORD-2023-112666 | Y6: Africa | Z6: Q1 | AA6: 28.38 | AB6: 0.1-0.2 | AE6: =X6 -> ORD-2023-112666 | AF6: =Y6 -> Africa | AG6: =Z6 -> Q1 | AH6: =AA6 -> 28.38 | AI6: =AB6 -> 0.1-0.2
A7: Apr | B7: 826169.28 | H7: Asia | I7: 154525.02 | J7: 82314.574 | K7: 35587.827 | L7: 110282.29 | M7: 76616.392 | N7: 13685.927 | O7: 473012.03 | R7: NET-1612 | S7: 34798.744 | T7: 0.54738809 | X7: ORD-2023-125739 | Y7: Africa | Z7: Q2 | AA7: 327.97 | AB7: 0-0.1 | AE7: =X7 -> ORD-2023-125739 | AF7: =Y7 -> Africa | AG7: =Z7 -> Q2 | AH7: =AA7 -> 327.97 | AI7: =AB7 -> 0-0.1
A8: May | B8: 1143465.3 | H8: Europe | I8: 181830.29 | J8: 76156.021 | K8: 43264.465 | L8: 132913.82 | M8: 120954.58 | N8: 7009.1658 | O8: 562128.35 | R8: LAP-8825 | S8: 32830.14 | T8: 0.56547483 | X8: ORD-2023-126505 | Y8: Americas | Z8: Q4 | AA8: 856.1 | AB8: 0-0.1 | AE8: =X8 -> ORD-2023-126505 | AF8: =Y8 -> Americas | AG8: =Z8 -> Q4 | AH8: =AA8 -> 856.1 | AI8: =AB8 -> 0-0.1
A9: Jun | B9: 1129353.9 | H9: Grand Total | I9: 639650.04 | J9: 378573.5 | K9: 228594.1 | L9: 518068.59 | M9: 312639.82 | N9: 34335.311 | O9: 2111861.4 | R9: CMP-8851 | S9: 32063.754 | T9: 0.27803664 | X9: ORD-2023-128295 | Y9: Africa | Z9: Q2 | AA9: 337.75 | AB9: 0-0.1 | AE9: =X9 -> ORD-2023-128295 | AF9: =Y9 -> Africa | AG9: =Z9 -> Q2 | AH9: =AA9 -> 337.75 | AI9: =AB9 -> 0-0.1
A10: Jul | B10: 1150273.2 | R10: PHN-8368 | S10: 31475.33 | T10: 0.59634877 | X10: ORD-2023-132101 | Y10: Americas | Z10: Q3 | AA10: 1279.56 | AB10: 0.1-0.2 | AE10: =X10 -> ORD-2023-132101 | AF10: =Y10 -> Americas | AG10: =Z10 -> Q3 | AH10: =AA10 -> 1279.56 | AI10: =AB10 -> 0.1-0.2
A11: Aug | B11: 961205.12 | R11: LAP-8910 | S11: 30931.04 | T11: 0.35928876 | X11: ORD-2023-133848 | Y11: Americas | Z11: Q3 | AA11: 590.33 | AB11: 0-0.1 | AE11: =X11 -> ORD-2023-133848 | AF11: =Y11 -> Americas | AG11: =Z11 -> Q3 | AH11: =AA11 -> 590.33 | AI11: =AB11 -> 0-0.1
A12: Sep | B12: 571165.24 | R12: ACC-6626 | S12: 28504.179 | T12: 0.40182381 | X12: ORD-2023-139236 | Y12: Asia | Z12: Q1 | AA12: 1171.17 | AB12: 0.1-0.2 | AE12: =X12 -> ORD-2023-139236 | AF12: =Y12 -> Asia | AG12: =Z12 -> Q1 | AH12: =AA12 -> 1171.17 | AI12: =AB12 -> 0.1-0.2
A13: Oct | B13: 560649.84 | R13: LAP-6499 | S13: 28191.999 | T13: 0.48797306 | X13: ORD-2023-144816 | Y13: Africa | Z13: Q2 | AA13: 653.86 | AB13: 0.1-0.2 | AE13: =X13 -> ORD-2023-144816 | AF13: =Y13 -> Africa | AG13: =Z13 -> Q2 | AH13: =AA13 -> 653.86 | AI13: =AB13 -> 0.1-0.2
A14: Nov | B14: 466577.44 | R14: Grand Total | S14: 372055.06 | T14: 0.49227574 | X14: ORD-2023-156396 | Y14: Africa | Z14: Q1 | AA14: 352.65 | AB14: 0-0.1 | AE14: =X14 -> ORD-2023-156396 | AF14: =Y14 -> Africa | AG14: =Z14 -> Q1 | AH14: =AA14 -> 352.65 | AI14: =AB14 -> 0-0.1
A15: Dec | B15: 656137.94 | X15: ORD-2023-157993 | Y15: Asia | Z15: Q2 | AA15: 329.03 | AB15: 0.1-0.2 | AE15: =X15 -> ORD-2023-157993 | AF15: =Y15 -> Asia | AG15: =Z15 -> Q2 | AH15: =AA15 -> 329.03 | AI15: =AB15 -> 0.1-0.2
A16: Grand Total | B16: 9639609.1 | X16: ORD-2023-159379 | Y16: Africa | Z16: Q1 | AA16: 1410.05 | AB16: 0.1-0.2 | AE16: =X16 -> ORD-2023-159379 | AF16: =Y16 -> Africa | AG16: =Z16 -> Q1 | AH16: =AA16 -> 1410.05 | AI16: =AB16 -> 0.1-0.2
X17: ORD-2023-159821 | Y17: Africa | Z17: Q3 | AA17: 834.26 | AB17: 0-0.1 | AE17: =X17 -> ORD-2023-159821 | AF17: =Y17 -> Africa | AG17: =Z17 -> Q3 | AH17: =AA17 -> 834.26 | AI17: =AB17 -> 0-0.1
X18: ORD-2023-163610 | Y18: Americas | Z18: Q4 | AA18: 1373.31 | AB18: 0.2-0.3 | AE18: =X18 -> ORD-2023-163610 | AF18: =Y18 -> Americas | AG18: =Z18 -> Q4 | AH18: =AA18 -> 1373.31 | AI18: =AB18 -> 0.2-0.3
X19: ORD-2023-166668 | Y19: Asia | Z19: Q4 | AA19: 649.91 | AB19: 0.1-0.2 | AE19: =X19 -> ORD-2023-166668 | AF19: =Y19 -> Asia | AG19: =Z19 -> Q4 | AH19: =AA19 -> 649.91 | AI19: =AB19 -> 0.1-0.2
X20: ORD-2023-172095 | Y20: Americas | Z20: Q2 | AA20: 813.97 | AB20: 0-0.1 | AE20: =X20 -> ORD-2023-172095 | AF20: =Y20 -> Americas | AG20: =Z20 -> Q2 | AH20: =AA20 -> 813.97 | AI20: =AB20 -> 0-0.1
X21: ORD-2023-173313 | Y21: Europe | Z21: Q2 | AA21: 751.28 | AB21: 0.1-0.2 | AE21: =X21 -> ORD-2023-173313 | AF21: =Y21 -> Europe | AG21: =Z21 -> Q2 | AH21: =AA21 -> 751.28 | AI21: =AB21 -> 0.1-0.2
X22: ORD-2023-177794 | Y22: Americas | Z22: Q2 | AA22: 249.71 | AB22: 0-0.1 | AE22: =X22 -> ORD-2023-177794 | AF22: =Y22 -> Americas | AG22: =Z22 -> Q2 | AH22: =AA22 -> 249.71 | AI22: =AB22 -> 0-0.1
X23: ORD-2023-178249 | Y23: Africa | Z23: Q4 | AA23: 1395.49 | AB23: 0.2-0.3 | AE23: =X23 -> ORD-2023-178249 | AF23: =Y23 -> Africa | AG23: =Z23 -> Q4 | AH23: =AA23 -> 1395.49 | AI23: =AB23 -> 0.2-0.3
X24: ORD-2023-181257 | Y24: Europe | Z24: Q4 | AA24: 1184.99 | AB24: 0-0.1 | AE24: =X24 -> ORD-2023-181257 | AF24: =Y24 -> Europe | AG24: =Z24 -> Q4 | AH24: =AA24 -> 1184.99 | AI24: =AB24 -> 0-0.1
X25: ORD-2023-184577 | Y25: Asia | Z25: Q2 | AA25: 979.59 | AB25: 0.1-0.2 | AE25: =X25 -> ORD-2023-184577 | AF25: =Y25 -> Asia | AG25: =Z25 -> Q2 | AH25: =AA25 -> 979.59 | AI25: =AB25 -> 0.1-0.2
X26: ORD-2023-191563 | Y26: Europe | Z26: Q4 | AA26: 174.74 | AB26: 0.1-0.2 | AE26: =X26 -> ORD-2023-191563 | AF26: =Y26 -> Europe | AG26: =Z26 -> Q4 | AH26: =AA26 -> 174.74 | AI26: =AB26 -> 0.1-0.2
X27: ORD-2023-192324 | Y27: Europe | Z27: Q3 | AA27: 376.83 | AB27: 0.1-0.2 | AE27: =X27 -> ORD-2023-192324 | AF27: =Y27 -> Europe | AG27: =Z27 -> Q3 | AH27: =AA27 -> 376.83 | AI27: =AB27 -> 0.1-0.2
X28: ORD-2023-195665 | Y28: Americas | Z28: Q4 | AA28: 1080.43 | AB28: 0.1-0.2 | AE28: =X28 -> ORD-2023-195665 | AF28: =Y28 -> Americas | AG28: =Z28 -> Q4 | AH28: =AA28 -> 1080.43 | AI28: =AB28 -> 0.1-0.2
... X101: ORD-2023-521818 | Y101: Americas | Z101: Q1 | AA101: 413.52 | AB101: 0.1-0.2 | AE101: =X101 -> ORD-2023-521818 | AF101: =Y101 -> Americas | AG101: =Z101 -> Q1 | AH101: =AA101 -> 413.52 | AI101: =AB101 -> 0.1-0.2
Y102: Asia | Z102: Q1 | AA102: 1262.1 | AB102: 0.2-0.3 | AE102: =X102 -> 0 | AF102: =Y102 -> Asia | AG102: =Z102 -> Q1 | AH102: =AA102 -> 1262.1 | AI102: =AB102 -> 0.2-0.3
X103: ORD-2023-525643 | Y103: Africa | Z103: Q3 | AA103: 676.37 | AB103: 0-0.1 | AE103: =X103 -> ORD-2023-525643 | AF103: =Y103 -> Africa | AG103: =Z103 -> Q3 | AH103: =AA103 -> 676.37 | AI103: =AB103 -> 0-0.1
X104: ORD-2023-536542 | Y104: Africa | Z104: Q2 | AA104: 894.23 | AB104: 0.1-0.2 | AE104: =X104 -> ORD-2023-536542 | AF104: =Y104 -> Africa | AG104: =Z104 -> Q2 | AH104: =AA104 -> 894.23 | AI104: =AB104 -> 0.1-0.2
X105: ORD-2023-539967 | Y105: Asia | Z105: Q3 | AA105: 141.26 | AB105: 0.1-0.2 | AE105: =X105 -> ORD-2023-539967 | AF105: =Y105 -> Asia | AG105: =Z105 -> Q3 | AH105: =AA105 -> 141.26 | AI105: =AB105 -> 0.1-0.2
X106: ORD-2023-545150 | Y106: Africa | Z106: Q2 | AA106: 720.35 | AB106: 0.1-0.2 | AE106: =X106 -> ORD-2023-545150 | AF106: =Y106 -> Africa | AG106: =Z106 -> Q2 | AH106: =AA106 -> 720.35 | AI106: =AB106 -> 0.1-0.2
X107: ORD-2023-548874 | Y107: Europe | Z107: Q1 | AA107: 1082.17 | AB107: 0.1-0.2 | AE107: =X107 -> ORD-2023-548874 | AF107: =Y107 -> Europe | AG107: =Z107 -> Q1 | AH107: =AA107 -> 1082.17 | AI107: =AB107 -> 0.1-0.2
X108: ORD-2023-548934 | Y108: Asia | Z108: Q3 | AA108: 226.04 | AB108: 0.1-0.2 | AE108: =X108 -> ORD-2023-548934 | AF108: =Y108 -> Asia | AG108: =Z108 -> Q3 | AH108: =AA108 -> 226.04 | AI108: =AB108 -> 0.1-0.2
X109: ORD-2023-552115 | Y109: Americas | Z109: Q3 | AA109: 689.33 | AB109: 0.1-0.2 | AE109: =X109 -> ORD-2023-552115 | AF109: =Y109 -> Americas | AG109: =Z109 -> Q3 | AH109: =AA109 -> 689.33 | AI109: =AB109 -> 0.1-0.2
X110: ORD-2023-561823 | Y110: Asia | Z110: Q4 | AA110: 1349.04 | AB110: 0.1-0.2 | AE110: =X110 -> ORD-2023-561823 | AF110: =Y110 -> Asia | AG110: =Z110 -> Q4 | AH110: =AA110 -> 1349.04 | AI110: =AB110 -> 0.1-0.2
X111: ORD-2023-562894 | Y111: Americas | Z111: Q1 | AA111: 1242.66 | AB111: 0-0.1 | AE111: =X111 -> ORD-2023-562894 | AF111: =Y111 -> Americas | AG111: =Z111 -> Q1 | AH111: =AA111 -> 1242.66 | AI111: =AB111 -> 0-0.1
X112: ORD-2023-568013 | Y112: Asia | Z112: Q3 | AA112: 649.13 | AB112: 0.1-0.2 | AE112: =X112 -> ORD-2023-568013 | AF112: =Y112 -> Asia | AG112: =Z112 -> Q3 | AH112: =AA112 -> 649.13 | AI112: =AB112 -> 0.1-0.2
X113: ORD-2023-569862 | Y113: Europe | Z113: Q3 | AA113: 1039.03 | AB113: 0.2-0.3 | AE113: =X113 -> ORD-2023-569862 | AF113: =Y113 -> Europe | AG113: =Z113 -> Q3 | AH113: =AA113 -> 1039.03 | AI113: =AB113 -> 0.2-0.3
X114: ORD-2023-573146 | Y114: Asia | Z114: Q4 | AA114: 1495.79 | AB114: 0-0.1 | AE114: =X114 -> ORD-2023-573146 | AF114: =Y114 -> Asia | AG114: =Z114 -> Q4 | AH114: =AA114 -> 1495.79 | AI114: =AB114 -> 0-0.1
...

Sheet Analysis 2
A2: First date of sale by year month & country; total gross revenue by month
A4: Year order was placed | B4: 2023 | H4: Salesperson | I4: (All)
A6: Months (Order Date) | B6: Country | C6: Min of Order Date | D6: Sum of Gross Revenue | H6: Region | I6: Discount % | J6: Count of Order ID | K6: Average of Gross Revenue2 | L6: Sum of Gross Revenue | O6: All salespeople
A7: Jan | B7: Canada | C7: 44928 | D7: 4141.76 | H7: Africa | I7: 0-0.1 | J7: 59 | K7: 17997.546 | L7: 1061855.2 | O7: Africa | P7: Americas | Q7: Asia | R7: Europe
B8: South Africa | C8: 44933 | D8: 2679.9406 | I8: 0.1-0.2 | J8: 64 | K8: 14607.302 | L8: 934867.32 | N8: < 10% | O8: 59 | P8: 56 | Q8: 61 | R8: 66
B9: France | C9: 44936 | D9: 8970.8319 | I9: 0.2-0.3 | J9: 19 | K9: 13990.198 | L9: 265813.76 | N9: < 20% | O9: 64 | P9: 73 | Q9: 86 | R9: 75
B10: China | C10: 44938 | D10: 11406.96 | I10: 0.3-0.4 | J10: 2 | K10: 11888 | L10: 23776 | N10: < 30% | O10: 19 | P10: 27 | Q10: 21 | R10: 18
B11: USA | C11: 44939 | D11: 28398.352 | I11: 0.5-0.6 | J11: 1 | K11: 7424.5532 | L11: 7424.5532 | N11: < 40% | O11: 2 | P11: 1 | Q11: 3
B12: Nigeria | C12: 44941 | D12: 552.16461 | H12: Americas | I12: 0-0.1 | J12: 56 | K12: 16697.216 | L12: 935044.1 | N12: < 50%
B13: United Kingdom | C13: 44945 | D13: 24835.771 | I13: 0.1-0.2 | J13: 73 | K13: 15556.434 | L13: 1135619.7 | N13: < 60% | O13: 1
B14: Kenya | C14: 44946 | D14: 36307.777 | I14: 0.2-0.3 | J14: 27 | K14: 10912.124 | L14: 294627.34 | N14: Outliers > 20% | O14: =SUM(O10:O13) -> 22 | P14: =SUM(P10:P13) -> 28 | Q14: =SUM(Q10:Q13) -> 24 | R14: =SUM(R10:R13) -> 18
B15: Germany | C15: 44948 | D15: 11633.831 | I15: 0.3-0.4 | J15: 1 | K15: 4074.2515 | L15: 4074.2515
B16: India | C16: 44955 | D16: 20524.374 | H16: Asia | I16: 0-0.1 | J16: 61 | K16: 15008.421 | L16: 915513.7
B17: Brazil | C17: 44955 | D17: 1394.2895 | I17: 0.1-0.2 | J17: 86 | K17: 14948.861 | L17: 1285602
A18: Jan Total | C18: 44928 | D18: 150846.05 | I18: 0.2-0.3 | J18: 21 | K18: 10895.641 | L18: 228808.46
A19: Feb | B19: USA | C19: 44962 | D19: 61175.933 | I19: 0.3-0.4 | J19: 3 | K19: 17767.344 | L19: 53302.031
B20: Brazil | C20: 44964 | D20: 24720.17 | H20: Europe | I20: 0-0.1 | J20: 66 | K20: 17874.717 | L20: 1179731.3
B21: South Africa | C21: 44965 | D21: 73470.384 | I21: 0.1-0.2 | J21: 75 | K21: 14166.371 | L21: 1062477.8
B22: Nigeria | C22: 44968 | D22: 4457.7239 | I22: 0.2-0.3 | J22: 18 | K22: 13948.419 | L22: 251071.54
B23: Germany | C23: 44976 | D23: 127062.92 | H23: Grand Total | J23: 632 | K23: 15252.546 | L23: 9639609.1
B24: India | C24: 44977 | D24: 18583.827
B25: Kenya | C25: 44978 | D25: 2403.1784
B26: Canada | C26: 44980 | D26: 23822.982
B27: United Kingdom | C27: 44980 | D27: 3355.2104
B28: China | C28: 44980 | D28: 10119.209
B29: France | C29: 44985 | D29: 35473.457
A30: Feb Total | C30: 44962 | D30: 384644.99
A31: Mar | B31: Brazil | C31: 44987 | D31: 21874.522
B32: Japan | C32: 44988 | D32: 26361.249
B33: Canada | C33: 44989 | D33: 13910.315
B34: China | C34: 44991 | D34: 12577.313
B35: Kenya | C35: 44992 | D35: 60038.242
B36: South Africa | C36: 44998 | D36: 26029.557
B37: Germany | C37: 44999 | D37: 5345.7298
B38: United Kingdom | C38: 45004 | D38: 12987.096
B39: India | C39: 45012 | D39: 5961.8482
A40: Mar Total | C40: 44987 | D40: 185085.87
A41: Apr | B41: France | C41: 45019 | D41: 37793.811
B42: Canada | C42: 45021 | D42: 14054.046
B43: United Kingdom | C43: 45022 | D43: 62783.441
...

Sheet Analysis
A7: Salesperson productivity | G7: Channel mix & cannibalization | P7: Order count & gross revenue by regional hierarchy
A9: Row Labels | B9: Count of Order ID | C9: Sum of Gross Profit | G9: Sum of Gross Revenue | H9: Column Labels
A10: B. Chen | B10: 48 | C10: 228409.56 | G10: Row Labels | H10: Online | I10: Retail | J10: Grand Total | P10: Region | Q10: Country | R10: City | S10: Count of Order ID | T10: Sum of Gross Profit
A11: M. Rossi | B11: 48 | C11: 193178.46 | G11: Asia | H11: 374901.41 | I11: 616499.51 | J11: 991400.93 | P11: Africa | Q11: Kenya | R11: Kisumu | S11: 18 | T11: 99767.351
A12: L. Okafor | B12: 46 | C12: 182460.09 | G12: Europe | H12: 518253.38 | I12: 435678.52 | J12: 953931.91 | R12: Mombasa | S12: 14 | T12: 32851.368
A13: A. Patel | B13: 46 | C13: 177343.11 | G13: Americas | H13: 609852.19 | I13: 261137.88 | J13: 870990.07 | R13: Nairobi | S13: 13 | T13: 18550.922
A14: F. Müller | B14: 51 | C14: 176734.64 | G14: Africa | H14: 380980.28 | I14: 465299.39 | J14: 846279.66 | R14: Nakuru | S14: 11 | T14: 8587.3425
A15: J. Njeri | B15: 50 | C15: 168234.71 | G15: Grand Total | H15: 1883987.3 | I15: 1778615.3 | J15: 3662602.6 | Q15: Nigeria | R15: Port Harcourt | S15: 18 | T15: 55657.608
A16: K. Singh | B16: 44 | C16: 166868.11 | R16: Abuja | S16: 13 | T16: 46345.518
A17: E. Garcia | B17: 34 | C17: 153290.65 | R17: Lagos | S17: 12 | T17: 73291.408
A18: C. Otieno | B18: 37 | C18: 122107 | R18: Unattributed | S18: 1 | T18: 8326.2533
A19: G. Dubois | B19: 30 | C19: 119686.48 | Q19: South Africa | R19: Durban | S19: 17 | T19: 79139.446
A20: O. Wang | B20: 37 | C20: 94971.413 | R20: Johannesburg | S20: 15 | T20: 44732.367
A21: D. Smith | B21: 38 | C21: 92375.577 | R21: Cape Town | S21: 13 | T21: 66515.248
A22: N. Brown | B22: 32 | C22: 71331.831 | P22: Americas | Q22: Brazil | R22: Brasília | S22: 25 | T22: 67205.141
A23: I. Johnson | B23: 38 | C23: 69565.421 | R23: São Paulo | S23: 18 | T23: 110441.97
A24: Unattributed | B24: 8 | C24: 60871.899 | R24: Rio de Janeiro | S24: 18 | T24: 47751.044
A25: H. Kim | B25: 45 | C25: 34432.39 | R25: Unattributed | S25: 1 | T25: 7346.8945
A26: Grand Total | B26: 632 | C26: 2111861.4 | Q26: Canada | R26: Vancouver | S26: 17 | T26: 111902.32
R27: Toronto | S27: 15 | T27: 23067.861
R28: Montreal | S28: 11 | T28: 35301.538
R29: Unattributed | S29: 1 | T29: 11598.696
Q30: USA | R30: San Francisco | S30: 16 | T30: 45697.045
A31: Service level proxy | R31: Austin | S31: 14 | T31: 22780.392
R32: New York | S32: 13 | T32: 36739.136
A33: Country | B33: (All) | R33: Chicago | S33: 8 | T33: 23124.1
P34: Asia | Q34: China | R34: Shanghai | S34: 19 | T34: 55425.285
A35: Count of Product Category | B35: Column Labels | R35: Shenzhen | S35: 16 | T35: 79264.309
A36: Row Labels | B36: Accessories | C36: Components | D36: Laptops | E36: Monitors | F36: Networking | G36: Phones | H36: Printers | I36: Grand Total | R36: Beijing | S36: 15 | T36: 55674.273
A37: 0 | B37: 0.068181818 | C37: 0.021978022 | D37: 0.012195122 | E37: 0.021276596 | F37: 0.034883721 | G37: 0.022727273 | H37: 0.0097087379 | I37: 0.026898734 | R37: Unattributed | S37: 1 | T37: 97.006236
A38: 1 | B38: 0.034090909 | C38: 0.065934066 | D38: 0.036585366 | E38: 0.010638298 | F38: 0.023255814 | G38: 0.011363636 | H38: 0.0097087379 | I38: 0.026898734 | Q38: India | R38: Delhi | S38: 22 | T38: 45460.615
A39: 2 | B39: 0.056818182 | C39: 0.032967033 | D39: 0.012195122 | E39: 0.021276596 | F39: 0.023255814 | G39: 0.022727273 | H39: 0.038834951 | I39: 0.030063291 | R39: Bengaluru | S39: 16 | T39: 39397.704
A40: 3 | B40: 0.068181818 | C40: 0.010989011 | D40: 0.036585366 | E40: 0.042553191 | F40: 0.011627907 | G40: 0.011363636 | H40: 0.019417476 | I40: 0.028481013 | L40: Lead times | R40: Mumbai | S40: 13 | T40: 61192.106
A41: 4 | B41: 0.022727273 | C41: 0.032967033 | D41: 0.036585366 | E41: 0.031914894 | F41: 0.058139535 | G41: 0.022727273 | H41: 0.029126214 | I41: 0.033227848 | L41: 0-7 days | M41: Greater than 7 days | R41: Hyderabad | S41: 7 | T41: -16749.782
A42: 5 | B42: 0.011363636 | C42: 0.021978022 | D42: 0.036585366 | E42: 0.010638298 | F42: 0.034883721 | G42: 0.011363636 | H42: 0.029126214 | I42: 0.022151899 | K42: Accessories | L42: =ROUND(COUNTIF('Working Data'!$K:$K,Analysis!$K42)*SUM($B$37:$B$44),0) -> 28 | M42: =ROUND(COUNTIF('Working Data'!$K:$K,Analysis!$K42)*SUM($B$45:$B$68),0) -> 60 | N42: =SUM(L42:M42) -> 88 | O42: =L42/N42 -> 0.31818182 | R42: Unattributed | S42: 3 | T42: 13307.361
A43: 6 | B43: 0.034090909 | C43: 0.032967033 | D43: 0.06097561 | E43: 0 | F43: 0.011627907 | G43: 0.045454545 | H43: 0.029126214 | I43: 0.030063291 | K43: Components | L43: =ROUND(COUNTIF('Working Data'!$K:$K,Analysis!$K43)*SUM($B$37:$B$44),0) -> 29 | M43: =ROUND(COUNTIF('Working Data'!$K:$K,Analysis!$K43)*SUM($B$45:$B$68),0) -> 62 | N43: =SUM(L43:M43) -> 91 | O43: =L43/N43 -> 0.31868132 | Q43: Japan | R43: Nagoya | S43: 21 | T43: 57320.938
A44: 7 | B44: 0.022727273 | C44: 0 | D44: 0.048780488 | E44: 0.021276596 | F44: 0 | G44: 0.022727273 | H44: 0.029126214 | I44: 0.02056962 | K44: Laptops | L44: =ROUND(COUNTIF('Working Data'!$K:$K,Analysis!$K44)*SUM($B$37:$B$44),0) -> 26 | M44: =ROUND(COUNTIF('Working Data'!$K:$K,Analysis!$K44)*SUM($B$45:$B$68),0) -> 56 | N44: =SUM(L44:M44) -> 82 | O44: =L44/N44 -> 0.31707317 | R44: Osaka | S44: 20 | T44: 20216.486
A45: 8 | B45: 0.022727273 | C45: 0 | D45: 0.036585366 | E45: 0.031914894 | F45: 0.023255814 | G45: 0.068181818 | H45: 0.038834951 | I45: 0.03164557 | K45: Monitors | L45: =ROUND(COUNTIF('Working Data'!$K:$K,Analysis!$K45)*SUM($B$37:$B$44),0) -> 30 | M45: =ROUND(COUNTIF('Working Data'!$K:$K,Analysis!$K45)*SUM($B$45:$B$68),0) -> 64 | N45: =SUM(L45:M45) -> 94 | O45: =L45/N45 -> 0.31914894 | R45: Tokyo | S45: 18 | T45: 62405.729
A46: 9 | B46: 0.034090909 | C46: 0.032967033 | D46: 0.024390244 | E46: 0.031914894 | F46: 0.034883721 | G46: 0.034090909 | H46: 0.029126214 | I46: 0.03164557 | K46: Networking | L46: =ROUND(COUNTIF('Working Data'!$K:$K,Analysis!$K46)*SUM($B$37:$B$44),0) -> 27 | M46: =ROUND(COUNTIF('Working Data'!$K:$K,Analysis!$K46)*SUM($B$45:$B$68),0) -> 59 | N46: =SUM(L46:M46) -> 86 | O46: =L46/N46 -> 0.31395349 | P46: Europe | Q46: France | R46: Marseille | S46: 22 | T46: -23068.537
A47: 10 | B47: 0.011363636 | C47: 0.021978022 | D47: 0.06097561 | E47: 0.031914894 | F47: 0.023255814 | G47: 0.034090909 | H47: 0.019417476 | I47: 0.028481013 | K47: Phones | L47: =ROUND(COUNTIF('Working Data'!$K:$K,Analysis!$K47)*SUM($B$37:$B$44),0) -> 28 | M47: =ROUND(COUNTIF('Working Data'!$K:$K,Analysis!$K47)*SUM($B$45:$B$68),0) -> 60 | N47: =SUM(L47:M47) -> 88 | O47: =L47/N47 -> 0.31818182 | R47: Lyon | S47: 19 | T47: 76425.177
...

Sheet Working Data
A1: Order ID | B1: Order Date | C1: Required Date | D1: Lead Time in days | E1: Region | F1: Country | G1: City | H1: Customer Segment | I1: Channel | J1: Salesperson | K1: Product Category | L1: SKU | M1: Quantity | N1: Increased Quantities simulation | O1: Unit Cost | P1: Cost of Goods | Q1: Unit Price | R1: Adjusted Unit Price | S1: Discount % | T1: Discount % limits | U1: Gross Revenue | V1: Gross Profit | W1: Profit Margin % | X1: Order Month & Year | Y1: Quarter | Z1: Price bands by quartile | AA1: Quarter | AB1: Order Month | AC1: Year order was placed
A2: ORD-2024-275203 | B2: 45362 | C2: 45388 | D2: =IFERROR(DATEDIF(B2,C2,"D"),"") -> 26 | E2: Africa | F2: Kenya | G2: Kisumu | H2: Corporate | I2: Retail | J2: C. Otieno | K2: Components | L2: CMP-8270 | M2: 9 | N2: =ROUND(IF('Dashboard Visualization'!$U$3="",'Working Data'!M2,(('Dashboard Visualization'!U3+100%)*'Working Data'!M2)),0) -> 9 | O2: 279.24 | P2: =IF('Dashboard Visualization'!$U$2="",'Working Data'!$O2*'Working Data'!$N2,'Working Data'!$O2*'Working Data'!$N2*(100%+'Dashboard Visualization'!$U$2)) -> 2513.16 | Q2: 608.9 | R2: =(1-T2)*Q2 -> 540.7032 | S2: 0.112 | T2: =IF('Dashboard Visualization'!$U$1="",$S2,IF(S2>'Dashboard Visualization'!$U$1,'Dashboard Visualization'!$U$1,S2)) -> 0.112 | U2: =IFERROR(R2*(1-T2)*N2,"-") -> 4321.3 | V2: =IFERROR(U2-P2,"-") -> 1808.14 | W2: =IFERROR(IF(V2<=0,0,V2/U2),0) -> 0.41842501 | X2: =TEXT(B2,"MMM-YYYY") -> Mar-2024 | Y2: ="Q" & ROUNDUP(MONTH(X2)/3,0) & "-" & TEXT(X2,"YYYY") -> Q1-2024 | Z2: =IF(R2<QUARTILE(R:R,1), "Low Price", IF(R2<QUARTILE(R:R,3), "High Price", "Medium Price")) -> High Price | AA2: ="Q"&ROUNDUP(MONTH(X2)/3,0) -> Q1 | AB2: =TEXT(X2,"MMM") -> Mar | AC2: =TEXT(X2,"YYYY") -> 2024
A3: ORD-2024-358795 | B3: 45588 | C3: 45587 | D3: =IFERROR(DATEDIF(B3,C3,"D"),"") | E3: Africa | F3: Nigeria | G3: Port Harcourt | H3: Education | I3: Online | J3: J. Njeri | K3: Printers | L3: PRN-9322 | M3: 31 | N3: =ROUND(IF('Dashboard Visualization'!$U$3="",'Working Data'!$M3,'Working Data'!$M3*(100% +'Dashboard Visualization'!$U$3)),0) -> 31 | O3: 1084.39 | P3: =IF('Dashboard Visualization'!$U$2="",'Working Data'!$O3*'Working Data'!$N3,'Working Data'!$O3*'Working Data'!$N3*(100%+'Dashboard Visualization'!$U$2)) -> 33616.09 | Q3: 759.33 | R3: =(1-T3)*Q3 -> 579.36879 | S3: 0.237 | T3: =IF('Dashboard Visualization'!$U$1="",$S3,IF(S3>'Dashboard Visualization'!$U$1,'Dashboard Visualization'!$U$1,S3)) -> 0.237 | U3: =IFERROR(R3*(1-T3)*N3,"-") -> 13703.81 | V3: =IFERROR(U3-P3,"-") -> -19912.28 | W3: =IFERROR(IF(V3<=0,0,V3/U3),0) -> 0 | X3: =TEXT(B3,"MMM-YYYY") -> Oct-2024 | Y3: ="Q" & ROUNDUP(MONTH(X3)/3,0) & "-" & TEXT(X3,"YYYY") -> Q4-2024 | Z3: =IF(R3<QUARTILE(R:R,1), "Low Price", IF(R3<QUARTILE(R:R,3), "High Price", "Medium Price")) -> High Price | AA3: ="Q"&ROUNDUP(MONTH(X3)/3,0) -> Q4 | AB3: =TEXT(X3,"MMM") -> Oct | AC3: =TEXT(X3,"YYYY") -> 2024
A4: ORD-2023-373538 | B4: 44985 | C4: 45010 | D4: =IFERROR(DATEDIF(B4,C4,"D"),"") -> 25 | E4: Africa | F4: Kenya | G4: Nairobi | H4: Corporate | I4: Retail | J4: I. Johnson | K4: Networking | L4: NET-9666 | M4: 12 | N4: =ROUND(IF('Dashboard Visualization'!$U$3="",'Working Data'!$M4,'Working Data'!$M4*(100% +'Dashboard Visualization'!$U$3)),0) -> 12 | O4: 1460.76 | P4: =IF('Dashboard Visualization'!$U$2="",'Working Data'!$O4*'Working Data'!$N4,'Working Data'!$O4*'Working Data'!$N4*(100%+'Dashboard Visualization'!$U$2)) -> 17529.12 | Q4: -30.66 | R4: =(1-T4)*Q4 -> -26.64354 | S4: 0.131 | T4: =IF('Dashboard Visualization'!$U$1="",$S4,IF(S4>'Dashboard Visualization'!$U$1,'Dashboard Visualization'!$U$1,S4)) -> 0.131 | U4: =IFERROR(R4*(1-T4)*N4,"-") -> -277.83884 | V4: =IFERROR(U4-P4,"-") -> -17806.959 | W4: =IFERROR(IF(V4<=0,0,V4/U4),0) -> 0 | X4: =TEXT(B4,"MMM-YYYY") -> Feb-2023 | Y4: ="Q" & ROUNDUP(MONTH(X4)/3,0) & "-" & TEXT(X4,"YYYY") -> Q1-2023 | Z4: =IF(R4<QUARTILE(R:R,1), "Low Price", IF(R4<QUARTILE(R:R,3), "High Price", "Medium Price")) -> Low Price | AA4: ="Q"&ROUNDUP(MONTH(X4)/3,0) -> Q1 | AB4: =TEXT(X4,"MMM") -> Feb | AC4: =TEXT(X4,"YYYY") -> 2023
A5: ORD-2025-168148 | B5: 45745 | C5: 45749 | D5: =IFERROR(DATEDIF(B5,C5,"D"),"") -> 4 | E5: Africa | F5: Nigeria | G5: Lagos | H5: Non-Profit | I5: Marketplace | J5: G. Dubois | K5: Phones | L5: PHN-4556 | M5: 22 | N5: =ROUND(IF('Dashboard Visualization'!$U$3="",'Working Data'!$M5,'Working Data'!$M5*(100% +'Dashboard Visualization'!$U$3)),0) -> 22 | O5: 259.93 | P5: =IF('Dashboard Visualization'!$U$2="",'Working Data'!$O5*'Working Data'!$N5,'Working Data'!$O5*'Working Data'!$N5*(100%+'Dashboard Visualization'!$U$2)) -> 5718.46 | Q5: 255.94 | R5: =(1-T5)*Q5 -> 237.51232 | S5: 0.072 | T5: =IF('Dashboard Visualization'!$U$1="",$S5,IF(S5>'Dashboard Visualization'!$U$1,'Dashboard Visualization'!$U$1,S5)) -> 0.072 | U5: =IFERROR(R5*(1-T5)*N5,"-") -> 4849.0515 | V5: =IFERROR(U5-P5,"-") -> -869.40847 | W5: =IFERROR(IF(V5<=0,0,V5/U5),0) -> 0 | X5: =TEXT(B5,"MMM-YYYY") -> Mar-2025 | Y5: ="Q" & ROUNDUP(MONTH(X5)/3,0) & "-" & TEXT(X5,"YYYY") -> Q1-2025 | Z5: =IF(R5<QUARTILE(R:R,1), "Low Price", IF(R5<QUARTILE(R:R,3), "High Price", "Medium Price")) -> Low Price | AA5: ="Q"&ROUNDUP(MONTH(X5)/3,0) -> Q1 | AB5: =TEXT(X5,"MMM") -> Mar | AC5: =TEXT(X5,"YYYY") -> 2025
A6: ORD-2023-824839 | B6: 45266 | C6: 45291 | D6: =IFERROR(DATEDIF(B6,C6,"D"),"") -> 25 | E6: Asia | F6: Japan | G6: Osaka | H6: Consumer | I6: Retail | J6: L. Okafor | K6: Printers | L6: PRN-8041 | M6: 15 | N6: =ROUND(IF('Dashboard Visualization'!$U$3="",'Working Data'!$M6,'Working Data'!$M6*(100% +'Dashboard Visualization'!$U$3)),0) -> 15 | O6: 663.03 | P6: =IF('Dashboard Visualization'!$U$2="",'Working Data'!$O6*'Working Data'!$N6,'Working Data'!$O6*'Working Data'!$N6*(100%+'Dashboard Visualization'!$U$2)) -> 9945.45 | Q6: 813.51 | R6: =(1-T6)*Q6 -> 730.53198 | S6: 0.102 | T6: =IF('Dashboard Visualization'!$U$1="",$S6,IF(S6>'Dashboard Visualization'!$U$1,'Dashboard Visualization'!$U$1,S6)) -> 0.102 | U6: =IFERROR(R6*(1-T6)*N6,"-") -> 9840.2658 | V6: =IFERROR(U6-P6,"-") -> -105.18423 | W6: =IFERROR(IF(V6<=0,0,V6/U6),0) -> 0 | X6: =TEXT(B6,"MMM-YYYY") -> Dec-2023 | Y6: ="Q" & ROUNDUP(MONTH(X6)/3,0) & "-" & TEXT(X6,"YYYY") -> Q4-2023 | Z6: =IF(R6<QUARTILE(R:R,1), "Low Price", IF(R6<QUARTILE(R:R,3), "High Price", "Medium Price")) -> High Price | AA6: ="Q"&ROUNDUP(MONTH(X6)/3,0) -> Q4 | AB6: =TEXT(X6,"MMM") -> Dec | AC6: =TEXT(X6,"YYYY") -> 2023
A7: ORD-2023-723587 | B7: 44928 | C7: 44931 | D7: =IFERROR(DATEDIF(B7,C7,"D"),"") -> 3 | E7: Americas | F7: Canada | G7: Toronto | H7: Corporate | I7: Distributor | J7: B. Chen | K7: Laptops | L7: LAP-8555 | M7: 7 | N7: =ROUND(IF('Dashboard Visualization'!$U$3="",'Working Data'!$M7,'Working Data'!$M7*(100% +'Dashboard Visualization'!$U$3)),0) -> 7 | O7: 315.87 | P7: =IF('Dashboard Visualization'!$U$2="",'Working Data'!$O7*'Working Data'!$N7,'Working Data'!$O7*'Working Data'!$N7*(100%+'Dashboard Visualization'!$U$2)) -> 2211.09 | Q7: 591.68 | R7: =(1-T7)*Q7 -> 591.68 | S7: 0 | T7: =IF('Dashboard Visualization'!$U$1="",$S7,IF(S7>'Dashboard Visualization'!$U$1,'Dashboard Visualization'!$U$1,S7)) -> 0 | U7: =IFERROR(R7*(1-T7)*N7,"-") -> 4141.76 | V7: =IFERROR(U7-P7,"-") -> 1930.67 | W7: =IFERROR(IF(V7<=0,0,V7/U7),0) -> 0.46614724 | X7: =TEXT(B7,"MMM-YYYY") -> Jan-2023 | Y7: ="Q" & ROUNDUP(MONTH(X7)/3,0) & "-" & TEXT(X7,"YYYY") -> Q1-2023 | Z7: =IF(R7<QUARTILE(R:R,1), "Low Price", IF(R7<QUARTILE(R:R,3), "High Price", "Medium Price")) -> High Price | AA7: ="Q"&ROUNDUP(MONTH(X7)/3,0) -> Q1 | AB7: =TEXT(X7,"MMM") -> Jan | AC7: =TEXT(X7,"YYYY") -> 2023
A8: ORD-2024-336584 | B8: 45653 | C8: 45671 | D8: =IFERROR(DATEDIF(B8,C8,"D"),"") -> 18 | E8: Asia | F8: India | G8: Bengaluru | H8: Small Business | I8: Marketplace | J8: E. Garcia | K8: Monitors | L8: MON-8629 | M8: 4 | N8: =ROUND(IF('Dashboard Visualization'!$U$3="",'Working Data'!$M8,'Working Data'!$M8*(100% +'Dashboard Visualization'!$U$3)),0) -> 4 | O8: 586.07 | P8: =IF('Dashboard Visualization'!$U$2="",'Working Data'!$O8*'Working Data'!$N8,'Working Data'!$O8*'Working Data'!$N8*(100%+'Dashboard Visualization'!$U$2)) -> 2344.28 | Q8: 845.97 | R8: =(1-T8)*Q8 -> 721.61241 | S8: 0.147 | T8: =IF('Dashboard Visualization'!$U$1="",$S8,IF(S8>'Dashboard Visualization'!$U$1,'Dashboard Visualization'!$U$1,S8)) -> 0.147 | U8: =IFERROR(R8*(1-T8)*N8,"-") -> 2462.1415 | V8: =IFERROR(U8-P8,"-") -> 117.86154 | W8: =IFERROR(IF(V8<=0,0,V8/U8),0) -> 0.047869524 | X8: =TEXT(B8,"MMM-YYYY") -> Dec-2024 | Y8: ="Q" & ROUNDUP(MONTH(X8)/3,0) & "-" & TEXT(X8,"YYYY") -> Q4-2024 | Z8: =IF(R8<QUARTILE(R:R,1), "Low Price", IF(R8<QUARTILE(R:R,3), "High Price", "Medium Price")) -> High Price | AA8: ="Q"&ROUNDUP(MONTH(X8)/3,0) -> Q4 | AB8: =TEXT(X8,"MMM") -> Dec | AC8: =TEXT(X8,"YYYY") -> 2024
A9: ORD-2023-112666 | B9: 44941 | C9: 44939 | D9: =IFERROR(DATEDIF(B9,C9,"D"),"") | E9: Africa | F9: Nigeria | G9: Abuja | H9: Education | I9: Online | J9: O. Wang | K9: Printers | L9: PRN-6276 | M9: 18 | N9: =ROUND(IF('Dashboard Visualization'!$U$3="",'Working Data'!$M9,'Working Data'!$M9*(100% +'Dashboard Visualization'!$U$3)),0) -> 18 | O9: 28.38 | P9: =IF('Dashboard Visualization'!$U$2="",'Working Data'!$O9*'Working Data'!$N9,'Working Data'!$O9*'Working Data'!$N9*(100%+'Dashboard Visualization'!$U$2)) -> 510.84 | Q9: 47.22 | R9: =(1-T9)*Q9 -> 38.05932 | S9: 0.194 | T9: =IF('Dashboard Visualization'!$U$1="",$S9,IF(S9>'Dashboard Visualization'!$U$1,'Dashboard Visualization'!$U$1,S9)) -> 0.194 | U9: =IFERROR(R9*(1-T9)*N9,"-") -> 552.16461 | V9: =IFERROR(U9-P9,"-") -> 41.324615 | W9: =IFERROR(IF(V9<=0,0,V9/U9),0) -> 0.074841113 | X9: =TEXT(B9,"MMM-YYYY") -> Jan-2023 | Y9: ="Q" & ROUNDUP(MONTH(X9)/3,0) & "-" & TEXT(X9,"YYYY") -> Q1-2023 | Z9: =IF(R9<QUARTILE(R:R,1), "Low Price", IF(R9<QUARTILE(R:R,3), "High Price", "Medium Price")) -> Low Price | AA9: ="Q"&ROUNDUP(MONTH(X9)/3,0) -> Q1 | AB9: =TEXT(X9,"MMM") -> Jan | AC9: =TEXT(X9,"YYYY") -> 2023
A10: ORD-2024-589570 | B10: 45416 | C10: 45441 | D10: =IFERROR(DATEDIF(B10,C10,"D"),"") -> 25 | E10: Africa | F10: Nigeria | G10: Abuja | H10: Non-Profit | I10: Marketplace | J10: O. Wang | K10: Monitors | L10: MON-6892 | M10: 6 | N10: =ROUND(IF('Dashboard Visualization'!$U$3="",'Working Data'!$M10,'Working Data'!$M10*(100% +'Dashboard Visualization'!$U$3)),0) -> 6 | O10: 1295.34 | P10: =IF('Dashboard Visualization'!$U$2="",'Working Data'!$O10*'Working Data'!$N10,'Working Data'!$O10*'Working Data'!$N10*(100%+'Dashboard Visualization'!$U$2)) -> 7772.04 | Q10: 2530.81 | R10: =(1-T10)*Q10 -> 2452.3549 | S10: 0.031 | T10: =IF('Dashboard Visualization'!$U$1="",$S10,IF(S10>'Dashboard Visualization'!$U$1,'Dashboard Visualization'!$U$1,S10)) -> 0.031 | U10: =IFERROR(R10*(1-T10)*N10,"-") -> 14257.991 | V10: =IFERROR(U10-P10,"-") -> 6485.9513 | W10: =IFERROR(IF(V10<=0,0,V10/U10),0) -> 0.45489937 | X10: =TEXT(B10,"MMM-YYYY") -> May-2024 | Y10: ="Q" & ROUNDUP(MONTH(X10)/3,0) & "-" & TEXT(X10,"YYYY") -> Q2-2024 | Z10: =IF(R10<QUARTILE(R:R,1), "Low Price", IF(R10<QUARTILE(R:R,3), "High Price", "Medium Price")) -> Medium Price | AA10: ="Q"&ROUNDUP(MONTH(X10)/3,0) -> Q2 | AB10: =TEXT(X10,"MMM") -> May | AC10: =TEXT(X10,"YYYY") -> 2024
A11: ORD-2025-997421 | B11: 45798 | C11: 45817 | D11: =IFERROR(DATEDIF(B11,C11,"D"),"") -> 19 | E11: Americas | F11: Brazil | G11: São Paulo | H11: Non-Profit | I11: Online | J11: A. Patel | K11: Components | L11: CMP-3731 | M11: 31 | N11: =ROUND(IF('Dashboard Visualization'!$U$3="",'Working Data'!$M11,'Working Data'!$M11*(100% +'Dashboard Visualization'!$U$3)),0) -> 31 | O11: 1331.38 | P11: =IF('Dashboard Visualization'!$U$2="",'Working Data'!$O11*'Working Data'!$N11,'Working Data'!$O11*'Working Data'!$N11*(100%+'Dashboard Visualization'!$U$2)) -> 41272.78 | Q11: 2309.56 | R11: =(1-T11)*Q11 -> 1965.4356 | S11: 0.149 | T11: =IF('Dashboard Visualization'!$U$1="",$S11,IF(S11>'Dashboard Visualization'!$U$1,'Dashboard Visualization'!$U$1,S11)) -> 0.149 | U11: =IFERROR(R11*(1-T11)*N11,"-") -> 51850.156 | V11: =IFERROR(U11-P11,"-") -> 10577.376 | W11: =IFERROR(IF(V11<=0,0,V11/U11),0) -> 0.20399892 | X11: =TEXT(B11,"MMM-YYYY") -> May-2025 | Y11: ="Q" & ROUNDUP(MONTH(X11)/3,0) & "-" & TEXT(X11,"YYYY") -> Q2-2025 | Z11: =IF(R11<QUARTILE(R:R,1), "Low Price", IF(R11<QUARTILE(R:R,3), "High Price", "Medium Price")) -> Medium Price | AA11: ="Q"&ROUNDUP(MONTH(X11)/3,0) -> Q2 | AB11: =TEXT(X11,"MMM") -> May | AC11: =TEXT(X11,"YYYY") -> 2025
A12: ORD-2024-210687 | B12: 45319 | C12: 45331 | D12: =IFERROR(DATEDIF(B12,C12,"D"),"") -> 12 | E12: Europe | F12: Germany | G12: Berlin | H12: Corporate | I12: Online | J12: G. Dubois | K12: Accessories | L12: ACC-7938 | M12: 23 | N12: =ROUND(IF('Dashboard Visualization'!$U$3="",'Working Data'!$M12,'Working Data'!$M12*(100% +'Dashboard Visualization'!$U$3)),0) -> 23 | O12: 644.17 | P12: =IF('Dashboard Visualization'!$U$2="",'Working Data'!$O12*'Working Data'!$N12,'Working Data'!$O12*'Working Data'!$N12*(100%+'Dashboard Visualization'!$U$2)) -> 14815.91 | Q12: 700.12 | R12: =(1-T12)*Q12 -> 695.91928 | S12: 0.006 | T12: =IF('Dashboard Visualization'!$U$1="",$S12,IF(S12>'Dashboard Visualization'!$U$1,'Dashboard Visualization'!$U$1,S12)) -> 0.006 | U12: =IFERROR(R12*(1-T12)*N12,"-") -> 15910.107 | V12: =IFERROR(U12-P12,"-") -> 1094.1966 | W12: =IFERROR(IF(V12<=0,0,V12/U12),0) -> 0.06877368 | X12: =TEXT(B12,"MMM-YYYY") -> Jan-2024 | Y12: ="Q" & ROUNDUP(MONTH(X12)/3,0) & "-" & TEXT(X12,"YYYY") -> Q1-2024 | Z12: =IF(R12<QUARTILE(R:R,1), "Low Price", IF(R12<QUARTILE(R:R,3), "High Price", "Medium Price")) -> High Price | AA12: ="Q"&ROUNDUP(MONTH(X12)/3,0) -> Q1 | AB12: =TEXT(X12,"MMM") -> Jan | AC12: =TEXT(X12,"YYYY") -> 2024
A13: ORD-2025-515515 | B13: 45660 | C13: 45680 | D13: =IFERROR(DATEDIF(B13,C13,"D"),"") -> 20 | E13: Asia | F13: Japan | G13: Osaka | H13: Corporate | I13: Distributor | J13: F. Müller | K13: Phones | L13: PHN-7019 | M13: 20 | N13: =ROUND(IF('Dashboard Visualization'!$U$3="",'Working Data'!$M13,'Working Data'!$M13*(100% +'Dashboard Visualization'!$U$3)),0) -> 20 | O13: 908.6 | P13: =IF('Dashboard Visualization'!$U$2="",'Working Data'!$O13*'Working Data'!$N13,'Working Data'!$O13*'Working Data'!$N13*(100%+'Dashboard Visualization'!$U$2)) -> 18172 | Q13: 691.37 | R13: =(1-T13)*Q13 -> 518.5275 | S13: 0.25 | T13: =IF('Dashboard Visualization'!$U$1="",$S13,IF(S13>'Dashboard Visualization'!$U$1,'Dashboard Visualization'!$U$1,S13)) -> 0.25 | U13: =IFERROR(R13*(1-T13)*N13,"-") -> 7777.9125 | V13: =IFERROR(U13-P13,"-") -> -10394.087 | W13: =IFERROR(IF(V13<=0,0,V13/U13),0) -> 0 | X13: =TEXT(B13,"MMM-YYYY") -> Jan-2025 | Y13: ="Q" & ROUNDUP(MONTH(X13)/3,0) & "-" & TEXT(X13,"YYYY") -> Q1-2025 | Z13: =IF(R13<QUARTILE(R:R,1), "Low Price", IF(R13<QUARTILE(R:R,3), "High Price", "Medium Price")) -> Low Price | AA13: ="Q"&ROUNDUP(MONTH(X13)/3,0) -> Q1 | AB13: =TEXT(X13,"MMM") -> Jan | AC13: =TEXT(X13,"YYYY") -> 2025
A14: ORD-2025-487261 | B14: 45722 | C14: 45747 | D14: =IFERROR(DATEDIF(B14,C14,"D"),"") -> 25 | E14: Americas | F14: Brazil | G14: Brasília | H14: Non-Profit | I14: Online | J14: J. Njeri | K14: Components | L14: CMP-3693 | M14: 10 | N14: =ROUND(IF('Dashboard Visualization'!$U$3="",'Working Data'!$M14,'Working Data'!$M14*(100% +'Dashboard Visualization'!$U$3)),0) -> 10 | O14: 331.57 | P14: =IF('Dashboard Visualization'!$U$2="",'Working Data'!$O14*'Working Data'!$N14,'Working Data'!$O14*'Working Data'!$N14*(100%+'Dashboard Visualization'!$U$2)) -> 3315.7 | Q14: 548.4 | R14: =(1-T14)*Q14 -> 496.8504 | S14: 0.094 | T14: =IF('Dashboard Visualization'!$U$1="",$S14,IF(S14>'Dashboard Visualization'!$U$1,'Dashboard Visualization'!$U$1,S14)) -> 0.094 | U14: =IFERROR(R14*(1-T14)*N14,"-") -> 4501.4646 | V14: =IFERROR(U14-P14,"-") -> 1185.7646 | W14: =IFERROR(IF(V14<=0,0,V14/U14),0) -> 0.26341751 | X14: =TEXT(B14,"MMM-YYYY") -> Mar-2025 | Y14: ="Q" & ROUNDUP(MONTH(X14)/3,0) & "-" & TEXT(X14,"YYYY") -> Q1-2025 | Z14: =IF(R14<QUARTILE(R:R,1), "Low Price", IF(R14<QUARTILE(R:R,3), "High Price", "Medium Price")) -> Low Price | AA14: ="Q"&ROUNDUP(MONTH(X14)/3,0) -> Q1 | AB14: =TEXT(X14,"MMM") -> Mar | AC14: =TEXT(X14,"YYYY") -> 2025
... A633: ORD-2025-728935 | B633: 45716 | C633: 45726 | D633: =IFERROR(DATEDIF(B633,C633,"D"),"") -> 10 | E633: Asia | F633: Japan | G633: Osaka | H633: Education | I633: Distributor | J633: N. Brown | K633: Laptops | L633: LAP-3017 | M633: 7 | N633: =ROUND(IF('Dashboard Visualization'!$U$3="",'Working Data'!$M633,'Working Data'!$M633*(100% +'Dashboard Visualization'!$U$3)),0) -> 7 | O633: 51.86 | P633: =IF('Dashboard Visualization'!$U$2="",'Working Data'!$O633*'Working Data'!$N633,'Working Data'!$O633*'Working Data'!$N633*(100%+'Dashboard Visualization'!$U$2)) -> 363.02 | Q633: 45.98 | R633: =(1-T633)*Q633 -> 38.02546 | S633: 0.173 | T633: =IF('Dashboard Visualization'!$U$1="",$S633,IF(S633>'Dashboard Visualization'!$U$1,'Dashboard Visualization'!$U$1,S633)) -> 0.173 | U633: =IFERROR(R633*(1-T633)*N633,"-") -> 220.12939 | V633: =IFERROR(U633-P633,"-") -> -142.89061 | W633: =IFERROR(IF(V633<=0,0,V633/U633),0) -> 0 | X633: =TEXT(B633,"MMM-YYYY") -> Feb-2025 | Y633: ="Q" & ROUNDUP(MONTH(X633)/3,0) & "-" & TEXT(X633,"YYYY") -> Q1-2025 | Z633: =IF(R633<QUARTILE(R:R,1), "Low Price", IF(R633<QUARTILE(R:R,3), "High Price", "Medium Price")) -> Low Price | AA633: ="Q"&ROUNDUP(MONTH(X633)/3,0) -> Q1 | AB633: =TEXT(X633,"MMM") -> Feb | AC633: =TEXT(X633,"YYYY") -> 2025

Sheet Brief
A1: Assignment
A2: Excel Mastery Assignment: Sales Operations & Analytics
A4: Overview:
A5: You are an analyst for a multi-regional electronics distributor. The 'Data' sheet contains 632 rows and 15 columns of transactional data with intentional data-quality issues.
A6: Your job is to clean, enrich, analyze, and present insights via a dynamic dashboard.
A8: Part A — Data Cleaning & Preparation:
A9: 1) Create a staging table where you:
A10: • Remove exact duplicate rows (define and document your duplicate criteria).
A11: • Fix data types (dates as Dates, numeric fields as numbers).
A12: • Handle missing values for City, Salesperson, and Channel using reasonable business logic (document your approach).
A13: • Flag and correct suspicious UnitPrice values (e.g., negative prices) and discounts (e.g., > 30%).
A14: • Ensure RequiredDate is not earlier than OrderDate; where it is, impute a corrected RequiredDate (explain your rule).
... A67: 15) Ensure your dashboard responds to slicers without broken references.

Sheet Original Data
A1: OrderID | B1: OrderDate | C1: RequiredDate | D1: Region | E1: Country | F1: City | G1: CustomerSegment | H1: Channel | I1: Salesperson | J1: ProductCategory | K1: SKU | L1: UnitCost | M1: UnitPrice | N1: DiscountPct | O1: Quantity
A2: ORD-2024-275203 | B2: 45362 | C2: 45388 | D2: Africa | E2: Kenya | F2: Kisumu | G2: Corporate | H2: Retail | I2: C. Otieno | J2: Components | K2: CMP-8270 | L2: 279.24 | M2: 608.9 | N2: 0.112 | O2: 9
A3: ORD-2024-358795 | B3: 45588 | C3: 45587 | D3: Africa | E3: Nigeria | F3: Port Harcourt | G3: Education | H3: Online | I3: J. Njeri | J3: Printers | K3: PRN-9322 | L3: 1084.39 | M3: 759.33 | N3: 0.237 | O3: 31
A4: ORD-2023-373538 | B4: 44985 | C4: 45010 | D4: Africa | E4: Kenya | F4: Nairobi | G4: Corporate | H4: Retail | I4: I. Johnson | J4: Networking | K4: NET-9666 | L4: 1460.76 | M4: -30.66 | N4: 0.131 | O4: 12
A5: ORD-2025-168148 | B5: 45745 | C5: 45749 | D5: Africa | E5: Nigeria | F5: Lagos | G5: Non-Profit | H5: Marketplace | I5: G. Dubois | J5: Phones | K5: PHN-4556 | L5: 259.93 | M5: 255.94 | N5: 0.072 | O5: 22
A6: ORD-2023-824839 | B6: 45266 | C6: 45291 | D6: Asia | E6: Japan | F6: Osaka | G6: Consumer | H6: Retail | I6: L. Okafor | J6: Printers | K6: PRN-8041 | L6: 663.03 | M6: 813.51 | N6: 0.102 | O6: 15
A7: ORD-2023-723587 | B7: 44928 | C7: 44931 | D7: Americas | E7: Canada | F7: Toronto | G7: Corporate | H7: Distributor | I7: B. Chen | J7: Laptops | K7: LAP-8555 | L7: 315.87 | M7: 591.68 | N7: 0 | O7: 7
A8: ORD-2024-336584 | B8: 45653 | C8: 45671 | D8: Asia | E8: India | F8: Bengaluru | G8: Small Business | H8: Marketplace | I8: E. Garcia | J8: Monitors | K8: MON-8629 | L8: 586.07 | M8: 845.97 | N8: 0.147 | O8: 4
A9: ORD-2023-112666 | B9: 44941 | C9: 44939 | D9: Africa | E9: Nigeria | F9: Abuja | G9: Education | H9: Online | I9: O. Wang | J9: Printers | K9: PRN-6276 | L9: 28.38 | M9: 47.22 | N9: 0.194 | O9: 18
A10: ORD-2024-589570 | B10: 45416 | C10: 45441 | D10: Africa | E10: Nigeria | F10: Abuja | G10: Non-Profit | H10: Marketplace | I10: O. Wang | J10: Monitors | K10: MON-6892 | L10: 1295.34 | M10: 2530.81 | N10: 0.031 | O10: 6
A11: ORD-2025-997421 | B11: 45798 | C11: 45817 | D11: Americas | E11: Brazil | F11: São Paulo | G11: Non-Profit | H11: Online | I11: A. Patel | J11: Components | K11: CMP-3731 | L11: 1331.38 | M11: 2309.56 | N11: 0.149 | O11: 31
A12: ORD-2024-210687 | B12: 45319 | C12: 45331 | D12: Europe | E12: Germany | F12: Berlin | G12: Corporate | H12: Online | I12: G. Dubois | J12: Accessories | K12: ACC-7938 | L12: 644.17 | M12: 700.12 | N12: 0.006 | O12: 23
A13: ORD-2025-515515 | B13: 45660 | C13: 45680 | D13: Asia | E13: Japan | F13: Osaka | G13: Corporate | H13: Distributor | I13: F. Müller | J13: Phones | K13: PHN-7019 | L13: 908.6 | M13: 691.37 | N13: 0.25 | O13: 20
... A34: ORD-2025-474710 | B34: 45862 | C34: 45875 | D34: Africa | E34: South Africa | F34: Johannesburg | G34: Education | H34: Marketplace | I34: D. Smith | J34: Networking | K34: NET-7966 | L34: 1463.9 | M34: 2633.02 | N34: 0.084 | O34: 4
A35: ORD-2024-629525 | B35: 45400 | C35: 45420 | D35: Europe | E35: United Kingdom | F35: London | G35: Non-Profit | I35: D. Smith | J35: Laptops | K35: LAP-9932 | L35: 645.33 | M35: 1321.85 | N35: 0 | O35: 10
A36: ORD-2024-167215 | B36: 45527 | C36: 45525 | D36: Africa | E36: South Africa | F36: Johannesburg | G36: Education | H36: Retail | I36: E. Garcia | J36: Components | K36: CMP-1559 | L36: 1432.52 | M36: 3036.87 | N36: 0 | O36: 9
A37: ORD-2023-864121 | B37: 45012 | C37: 45038 | D37: Asia | E37: India | F37: Delhi | G37: Non-Profit | H37: Marketplace | I37: J. Njeri | J37: Printers | K37: PRN-4506 | L37: 178.53 | M37: 199.37 | N37: 0.101 | O37: 37
A38: ORD-2024-692673 | B38: 45358 | C38: 45376 | D38: Europe | E38: Germany | F38: Munich | G38: Corporate | H38: Online | I38: B. Chen | J38: Components | K38: CMP-7617 | L38: 712.84 | M38: 927.51 | N38: 0.243 | O38: 27
A39: ORD-2025-718992 | B39: 45832 | C39: 45848 | D39: Asia | E39: China | F39: Shanghai | G39: Enterprise | H39: Direct | I39: N. Brown | J39: Components | K39: CMP-8390 | L39: 757.19 | M39: 1735.41 | N39: 0.136 | O39: 8
A40: ORD-2024-599522 | B40: 45401 | C40: 45418 | D40: Africa | E40: Nigeria | F40: Port Harcourt | G40: Non-Profit | H40: Online | I40: A. Patel | J40: Printers | K40: PRN-7303 | L40: 865.33 | M40: 1395.64 | N40: 0.175 | O40: 13
A41: ORD-2023-651638 | B41: 45094 | C41: 45101 | D41: Americas | E41: USA | F41: San Francisco | G41: Corporate | H41: Retail | I41: I. Johnson | J41: Printers | K41: PRN-6536 | L41: 313.99 | M41: 454.42 | N41: 0.129 | O41: 9
A42: ORD-2024-635626 | B42: 45531 | C42: 45554 | D42: Europe | E42: Germany | F42: Berlin | G42: Small Business | H42: Direct | I42: D. Smith | J42: Monitors | K42: MON-9967 | L42: 1024.01 | M42: 1580.97 | N42: 0.037 | O42: 27
A43: ORD-2024-296582 | B43: 45302 | C43: 45324 | D43: Africa | E43: South Africa | F43: Durban | G43: Consumer | H43: Online | I43: K. Singh | J43: Networking | K43: NET-1412 | L43: 1206.2 | M43: 1759.79 | N43: 0 | O43: 6
A44: ORD-2024-998320 | B44: 45590 | C44: 45610 | D44: Africa | E44: Kenya | F44: Mombasa | G44: Corporate | H44: Direct | I44: H. Kim | J44: Printers | K44: PRN-3143 | L44: 1396.48 | M44: 3204.5 | N44: 0.318 | O44: 14
A45: ORD-2025-820255 | B45: 45806 | C45: 45828 | D45: Europe | E45: Germany | F45: Berlin | G45: Corporate | H45: Direct | I45: A. Patel | J45: Printers | K45: PRN-9787 | L45: 483.47 | M45: 1135.43 | N45: 0.146 | O45: 11
A46: ORD-2024-389336 | B46: 45432 | C46: 45445 | D46: Americas | E46: Canada | F46: Vancouver | G46: Enterprise | H46: Marketplace | I46: K. Singh | J46: Components | K46: CMP-5946 | L46: 675.43 | M46: 996.36 | N46: 0.182 | O46: 22
A47: ORD-2023-308124 | B47: 45035 | C47: 45046 | D47: Asia | E47: India | F47: Delhi | G47: Small Business | H47: Retail | I47: A. Patel | J47: Networking | K47: NET-2062 | L47: 826.55 | M47: 1397.05 | N47: 0.169 | O47: 28
... A77: ORD-2023-722117 | B77: 45187 | C77: 45207 | D77: Asia | E77: India | F77: Delhi | G77: Small Business | H77: Direct | I77: B. Chen | J77: Components | K77: CMP-1009 | L77: 825.64 | M77: 1108.43 | N77: 0.114 | O77: 7
A78: ORD-2024-446699 | B78: 45532 | C78: 45560 | D78: Americas | E78: Brazil | F78: Rio de Janeiro | G78: Non-Profit | H78: Online | J78: Accessories | K78: ACC-4490 | L78: 1394.65 | M78: 3144.1 | N78: 0.134 | O78: 13
A79: ORD-2024-451005 | B79: 45473 | C79: 45471 | D79: Americas | E79: Brazil | F79: Rio de Janeiro | G79: Small Business | H79: Direct | I79: L. Okafor | J79: Accessories | K79: ACC-9162 | L79: 1112.98 | M79: 2095.73 | N79: 0.072 | O79: 17
A80: ORD-2023-290279 | B80: 45091 | C80: 45093 | D80: Europe | E80: United Kingdom | F80: Manchester | G80: Non-Profit | H80: Direct | I80: K. Singh | J80: Components | K80: CMP-5820 | L80: 357.36 | M80: 703.62 | N80: 0.257 | O80: 20
A81: ORD-2024-192263 | B81: 45617 | C81: 45647 | D81: Europe | E81: France | F81: Marseille | G81: Small Business | H81: Direct | I81: I. Johnson | J81: Monitors | K81: MON-7943 | L81: 1122.68 | M81: 1997.19 | N81: 0.186 | O81: 3
A82: ORD-2023-159379 | B82: 44965 | C82: 44968 | D82: Africa | E82: South Africa | F82: Cape Town | G82: Corporate | H82: Direct | I82: M. Rossi | J82: Networking | K82: NET-5018 | L82: 1410.05 | M82: 2763.95 | N82: 0.161 | O82: 26
A83: ORD-2023-343322 | B83: 45157 | C83: 45181 | D83: Americas | E83: Canada | F83: Vancouver | G83: Enterprise | H83: Retail | I83: I. Johnson | J83: Printers | K83: PRN-9669 | L83: 1183.95 | M83: 1503.53 | N83: 0.241 | O83: 16
A84: ORD-2025-114382 | B84: 45791 | C84: 45801 | D84: Europe | E84: France | F84: Paris | G84: Small Business | H84: Marketplace | I84: K. Singh | J84: Components | K84: CMP-2865 | L84: 170.39 | M84: 388.04 | N84: 0.084 | O84: 15
A85: ORD-2025-488349 | B85: 45770 | C85: 45769 | D85: Americas | E85: USA | F85: San Francisco | G85: Non-Profit | H85: Distributor | I85: D. Smith | J85: Monitors | K85: MON-3371 | L85: 23.24 | M85: 44.57 | N85: 0.215 | O85: 15
A86: ORD-2025-330203 | B86: 45741 | C86: 45764 | D86: Europe | E86: United Kingdom | F86: London | G86: Consumer | H86: Retail | I86: H. Kim | J86: Networking | K86: NET-7166 | L86: 1421.19 | M86: 1808.26 | N86: 0.104 | O86: 13
A87: ORD-2023-841426 | B87: 45282 | C87: 45283 | D87: Africa | E87: South Africa | F87: Cape Town | G87: Non-Profit | H87: Marketplace | I87: D. Smith | J87: Components | K87: CMP-4531 | L87: 1186.18 | M87: 1285.09 | N87: 0.07 | O87: 11
A88: ORD-2024-594592 | B88: 45388 | C88: 45407 | D88: Asia | E88: China | F88: Shanghai | G88: Corporate | H88: Retail | I88: K. Singh | J88: Components | K88: CMP-8196 | L88: 1366.48 | M88: 1678.14 | N88: 0.154 | O88: 10
A89: ORD-2025-863978 | B89: 45876 | C89: 45888 | D89: Africa | E89: Kenya | F89: Nakuru | G89: Corporate | I89: M. Rossi | J89: Components | K89: CMP-2854 | L89: 601.51 | M89: 679.35 | N89: 0.188 | O89: 3
...
